Traceback (most recent call last):
  File "/usr/local/pyenv/versions/3.11.11/lib/python3.11/site-packages/jupyter_cache/executors/utils.py", line 58, in single_nb_execution
    executenb(
  File "/usr/local/pyenv/versions/3.11.11/lib/python3.11/site-packages/nbclient/client.py", line 1319, in execute
    return NotebookClient(nb=nb, resources=resources, km=km, **kwargs).execute()
           ^^^^^^^^^^^^^^^^^^^^^^^^^^^^^^^^^^^^^^^^^^^^^^^^^^^^^^^^^^^^^^^^^^^^^
  File "/usr/local/pyenv/versions/3.11.11/lib/python3.11/site-packages/jupyter_core/utils/__init__.py", line 165, in wrapped
    return loop.run_until_complete(inner)
           ^^^^^^^^^^^^^^^^^^^^^^^^^^^^^^
  File "/usr/local/pyenv/versions/3.11.11/lib/python3.11/asyncio/base_events.py", line 654, in run_until_complete
    return future.result()
           ^^^^^^^^^^^^^^^
  File "/usr/local/pyenv/versions/3.11.11/lib/python3.11/site-packages/nbclient/client.py", line 709, in async_execute
    await self.async_execute_cell(
  File "/usr/local/pyenv/versions/3.11.11/lib/python3.11/site-packages/nbclient/client.py", line 1062, in async_execute_cell
    await self._check_raise_for_error(cell, cell_index, exec_reply)
  File "/usr/local/pyenv/versions/3.11.11/lib/python3.11/site-packages/nbclient/client.py", line 918, in _check_raise_for_error
    raise CellExecutionError.from_cell_and_msg(cell, exec_reply_content)
nbclient.exceptions.CellExecutionError: An error occurred while executing the following cell:
------------------
collection.progress_to_year(800)
------------------


[31m---------------------------------------------------------------------------[39m
[31mRemoteTraceback[39m                           Traceback (most recent call last)
[31mRemoteTraceback[39m: 
"""
Traceback (most recent call last):
  File "/usr/local/pyenv/versions/3.11.11/lib/python3.11/multiprocessing/pool.py", line 125, in worker
    result = (True, func(*args, **kwds))
                    ^^^^^^^^^^^^^^^^^^^
  File "/usr/local/pyenv/versions/3.11.11/lib/python3.11/multiprocessing/pool.py", line 48, in mapstar
    return list(map(*args))
           ^^^^^^^^^^^^^^^^
  File "/usr/local/pyenv/versions/3.11.11/lib/python3.11/site-packages/oggm_edu/glacier_collection.py", line 292, in _partial_progression
    glacier.progress_to_year(year)
  File "/usr/local/pyenv/versions/3.11.11/lib/python3.11/site-packages/oggm_edu/glacier.py", line 575, in progress_to_year
    out = model.run_until_and_store(year, fl_diag_path=None)
          ^^^^^^^^^^^^^^^^^^^^^^^^^^^^^^^^^^^^^^^^^^^^^^^^^^
  File "/usr/local/pyenv/versions/3.11.11/lib/python3.11/site-packages/oggm/core/flowline.py", line 1039, in run_until_and_store
    sects = [(np.zeros((ny, fl.nx)) * np.NaN) for fl in self.fls]
            ^^^^^^^^^^^^^^^^^^^^^^^^^^^^^^^^^^^^^^^^^^^^^^^^^^^^^
  File "/usr/local/pyenv/versions/3.11.11/lib/python3.11/site-packages/oggm/core/flowline.py", line 1039, in <listcomp>
    sects = [(np.zeros((ny, fl.nx)) * np.NaN) for fl in self.fls]
                                      ^^^^^^
  File "/usr/local/pyenv/versions/3.11.11/lib/python3.11/site-packages/numpy/__init__.py", line 400, in __getattr__
    raise AttributeError(
AttributeError: `np.NaN` was removed in the NumPy 2.0 release. Use `np.nan` instead.
"""

The above exception was the direct cause of the following exception:

[31mAttributeError[39m                            Traceback (most recent call last)
[36mCell[39m[36m [39m[32mIn[7][39m[32m, line 1[39m
[32m----> [39m[32m1[39m [43mcollection[49m[43m.[49m[43mprogress_to_year[49m[43m([49m[32;43m800[39;49m[43m)[49m

[36mFile [39m[32m/usr/local/pyenv/versions/3.11.11/lib/python3.11/site-packages/oggm_edu/glacier_collection.py:315[39m, in [36mGlacierCollection.progress_to_year[39m[34m(self, year)[39m
[32m    311[39m [38;5;66;03m# Pool context manager.[39;00m
[32m    312[39m [38;5;28;01mwith[39;00m Pool() [38;5;28;01mas[39;00m p:
[32m    313[39m     [38;5;66;03m# We use pool.map to evaluate the partial function on all glaciers in the collection.[39;00m
[32m    314[39m     [38;5;66;03m# After this, "update" the collection with the resulting glaciers.[39;00m
[32m--> [39m[32m315[39m     [38;5;28mself[39m._glaciers = [43mp[49m[43m.[49m[43mmap[49m[43m([49m[43mpartial_progression[49m[43m,[49m[43m [49m[38;5;28;43mself[39;49m[43m.[49m[43m_glaciers[49m[43m)[49m

[36mFile [39m[32m/usr/local/pyenv/versions/3.11.11/lib/python3.11/multiprocessing/pool.py:367[39m, in [36mPool.map[39m[34m(self, func, iterable, chunksize)[39m
[32m    362[39m [38;5;28;01mdef[39;00m[38;5;250m [39m[34mmap[39m([38;5;28mself[39m, func, iterable, chunksize=[38;5;28;01mNone[39;00m):
[32m    363[39m [38;5;250m    [39m[33;03m'''[39;00m
[32m    364[39m [33;03m    Apply `func` to each element in `iterable`, collecting the results[39;00m
[32m    365[39m [33;03m    in a list that is returned.[39;00m
[32m    366[39m [33;03m    '''[39;00m
[32m--> [39m[32m367[39m     [38;5;28;01mreturn[39;00m [38;5;28;43mself[39;49m[43m.[49m[43m_map_async[49m[43m([49m[43mfunc[49m[43m,[49m[43m [49m[43miterable[49m[43m,[49m[43m [49m[43mmapstar[49m[43m,[49m[43m [49m[43mchunksize[49m[43m)[49m[43m.[49m[43mget[49m[43m([49m[43m)[49m

[36mFile [39m[32m/usr/local/pyenv/versions/3.11.11/lib/python3.11/multiprocessing/pool.py:774[39m, in [36mApplyResult.get[39m[34m(self, timeout)[39m
[32m    772[39m     [38;5;28;01mreturn[39;00m [38;5;28mself[39m._value
[32m    773[39m [38;5;28;01melse[39;00m:
[32m--> [39m[32m774[39m     [38;5;28;01mraise[39;00m [38;5;28mself[39m._value

[31mAttributeError[39m: `np.NaN` was removed in the NumPy 2.0 release. Use `np.nan` instead.

